<?xml version="1.0" encoding="UTF-8"?><testsuite name="nosetests" tests="10" errors="0" failures="1" skip="0">
<testcase classname="test" name="test_add" time="0.001">
<failure type="exceptions.AssertionError" message=""><![CDATA[Traceback (most recent call last):
  File "C:\Python27\Lib\unittest\case.py", line 332, in run
    testMethod()
  File "C:\Python27\lib\site-packages\nose\case.py", line 197, in runTest
    self.test(*self.arg)
  File "E:\work\ktesttest\test.py", line 14, in test_add
    assert a2.addi(1,1) == 3
AssertionError
]]></failure>
</testcase>
<testcase classname="test" name="test_add3" time="0.001"></testcase>
<testcase classname="test" name="test_div" time="0.000"></testcase>
<testcase classname="test" name="test_divinverrt" time="0.001"></testcase>
<testcase classname="test" name="test_souss" time="0.001"></testcase>
<testcase classname="test" name="test_soussinvert" time="0.000"></testcase>
<testcase classname="test" name="test_mixdivandadd" time="0.001"></testcase>
<testcase classname="test" name="test_much" time="0.000"></testcase>
<testcase classname="test" name="test_conc" time="0.000"></testcase>
<testcase classname="test" name="test_nop" time="0.000"></testcase>
</testsuite>